Workbook

Sheet Read Me
A1: DATA INTELLIGENCE DASHBOARD | PROJECT GUIDE
A3: Dataset status | B3: Generated sample data (250 transactions). The original “Final Project Dataset” workbook was not provided; replace Raw Data with your real records before submission.
A4: Workbook sheets | B4: Raw Data, Analysis, Visualizations, Dashboard, and this guide.
A5: Refresh formulas | B5: Open in Excel and allow formulas to calculate. TODAY() and NOW() refresh when the workbook recalculates.
A6: Dashboard filters | B6: Use the Region, Category, and Segment dropdown cells on Dashboard. The formulas/charts are designed around the full dataset; use Excel table filters on Raw Data for detailed slicing.
A7: Timestamp | B7: Analysis!B4 uses NOW() with iterative calculation enabled so Excel preserves the last refresh timestamp.
A8: What-if analysis | B8: Analysis includes an editable revenue growth assumption and projected revenue formula. Use Data > What-If Analysis > Goal Seek or Scenario Manager in Excel for the class demonstration.
A9: Regression | B9: Analysis includes a monthly revenue trend and slope/intercept formulas using SLOPE and INTERCEPT; the Data Analysis ToolPak can also be used in Excel.
A10: Excel compatibility | B10: FILTER and UNIQUE formulas require Microsoft 365 or Excel 2021+. Other summaries use standard formulas.
A11: Visualizations | B11: Three charts are included: revenue by region, monthly revenue trend, and revenue by category.
A12: Generated on | B12: 2026-10-27

Sheet Raw Data
A1: Transaction_ID | B1: Date | C1: Customer_ID | D1: Customer_Name | E1: Product_ID | F1: Product_Name | G1: Category | H1: Quantity | I1: Unit_Price | J1: Payment_Method | K1: Region | L1: Customer_Segment | M1: Customer_Since | N1: Total_Amount
A2: TRX0001 | B2: 45395 | C2: CUST044 | D2: Cynthia Price | E2: P002 | F2: Smartphone | G2: Electronics | H2: 1 | I2: 699.99 | J2: Credit Card | K2: South | L2: Basic | M2: 44406 | N2: 699.99
A3: TRX0002 | B3: 45398 | C3: CUST047 | D3: Gerald Murphy | E3: P009 | F3: Monitor | G3: Electronics | H3: 1 | I3: 249.99 | J3: PayPal | K3: North | L3: Basic | M3: 44388 | N3: 249.99
A4: TRX0003 | B4: 45399 | C4: CUST015 | D4: Richard Lee | E4: P004 | F4: Coffee Maker | G4: Appliances | H4: 5 | I4: 79.99 | J4: Cash | K4: Central | L4: Basic | M4: 45313 | N4: 399.95
A5: TRX0004 | B5: 45401 | C5: CUST028 | D5: Betty Campbell | E5: P004 | F5: Coffee Maker | G5: Appliances | H5: 4 | I5: 79.99 | J5: Debit Card | K5: North | L5: Basic | M5: 45062 | N5: 319.96
A6: TRX0005 | B6: 45399 | C6: CUST023 | D6: Paul Baker | E6: P005 | F6: Blender | G6: Appliances | H6: 2 | I6: 59.99 | J6: Debit Card | K6: North | L6: Basic | M6: 44975 | N6: 119.98
A7: TRX0006 | B7: 45404 | C7: CUST008 | D7: Jennifer Taylor | E7: P006 | F7: Office Chair | G7: Furniture | H7: 3 | I7: 199.99 | J7: Debit Card | K7: North | L7: Premium | M7: 45137 | N7: 599.97
A8: TRX0007 | B8: 45401 | C8: CUST036 | D8: Nancy Collins | E8: P002 | F8: Smartphone | G8: Electronics | H8: 4 | I8: 699.99 | J8: Debit Card | K8: Central | L8: Standard | M8: 45379 | N8: 2799.96
A9: TRX0008 | B9: 45404 | C9: CUST014 | D9: Linda Martin | E9: P002 | F9: Smartphone | G9: Electronics | H9: 1 | I9: 699.99 | J9: Debit Card | K9: North | L9: Basic | M9: 44403 | N9: 699.99
A10: TRX0009 | B10: 45406 | C10: CUST026 | D10: Karen Hill | E10: P005 | F10: Blender | G10: Appliances | H10: 4 | I10: 59.99 | J10: Credit Card | K10: East | L10: Standard | M10: 44626 | N10: 239.96
A11: TRX0010 | B11: 45410 | C11: CUST046 | D11: Kathleen Bennett | E11: P005 | F11: Blender | G11: Appliances | H11: 1 | I11: 59.99 | J11: Credit Card | K11: Central | L11: Premium | M11: 44698 | N11: 59.99
A12: TRX0011 | B12: 45409 | C12: CUST012 | D12: Patricia Moore | E12: P008 | F12: Bookshelf | G12: Furniture | H12: 4 | I12: 149.99 | J12: Credit Card | K12: East | L12: Basic | M12: 44666 | N12: 599.96
A13: TRX0012 | B13: 45410 | C13: CUST003 | D13: Michael Brown | E13: P006 | F13: Office Chair | G13: Furniture | H13: 4 | I13: 199.99 | J13: Cash | K13: South | L13: Premium | M13: 44841 | N13: 799.96
... A251: TRX0250 | B251: 45758 | C251: CUST034 | D251: Carol Evans | E251: P003 | F251: Headphones | G251: Electronics | H251: 5 | I251: 149.99 | J251: Credit Card | K251: South | L251: Premium | M251: 44888 | N251: 749.95

Sheet Analysis
A1: ANALYSIS & WHAT-IF MODEL
A3: Last refreshed | B3: =NOW()
A4: Timestamp note | B4: Iterative calculation is enabled to retain a circular NOW() timestamp.
A6: KPI | B6: Value
A7: Total Revenue | B7: =SUM(Transactions[Total_Amount])
A8: Transaction Count | B8: =COUNTA(Transactions[Transaction_ID])
A9: Units Sold | B9: =SUM(Transactions[Quantity])
A10: Average Order Value | B10: =IFERROR(B7/B8,0)
A11: Unique Customers | B11: =SUMPRODUCT((Transactions[Customer_ID]<>"")/COUNTIF(Transactions[Customer_ID],Transactions[Customer_ID]&""))
A12: Revenue Growth Assumption | B12: 0.1
A13: Projected Revenue | B13: =B7*(1+B12)
A14: Days Since First Sale | B14: =DATEDIF(MIN(Transactions[Date]),TODAY(),"d")
A16: Monthly Revenue | B16: Units Sold | C16: Month End | E16: Region | F16: Revenue | H16: Category | I16: Revenue | K16: Customer | L16: Revenue | N16: Top Customer | O16: Revenue | Q16: Product | R16: Units
A17: =SUMIFS(Transactions[Total_Amount],Transactions[Date],">"&EOMONTH(C17,-1),Transactions[Date],"<="&C17) | B17: =SUMIFS(Transactions[Quantity],Transactions[Date],">"&EOMONTH(C17,-1),Transactions[Date],"<="&C17) | C17: =EOMONTH(MIN(Transactions[Date]),0) | E17: Central | F17: =SUMIF(Transactions[Region],E17,Transactions[Total_Amount]) | H17: Appliances | I17: =SUMIF(Transactions[Category],H17,Transactions[Total_Amount]) | K17: John Smith | L17: =SUMIF(Transactions[Customer_ID],"CUST001",Transactions[Total_Amount]) | N17: =INDEX(K17:K63,MATCH(MAX(L17:L63),L17:L63,0)) | O17: =MAX(L17:L63) | Q17: Laptop | R17: =SUMIF(Transactions[Product_Name],Q17,Transactions[Quantity])
A18: =SUMIFS(Transactions[Total_Amount],Transactions[Date],">"&EOMONTH(C18,-1),Transactions[Date],"<="&C18) | B18: =SUMIFS(Transactions[Quantity],Transactions[Date],">"&EOMONTH(C18,-1),Transactions[Date],"<="&C18) | C18: =EOMONTH(C17,1) | E18: East | F18: =SUMIF(Transactions[Region],E18,Transactions[Total_Amount]) | H18: Electronics | I18: =SUMIF(Transactions[Category],H18,Transactions[Total_Amount]) | K18: Emma Wilson | L18: =SUMIF(Transactions[Customer_ID],"CUST002",Transactions[Total_Amount]) | Q18: Smartphone | R18: =SUMIF(Transactions[Product_Name],Q18,Transactions[Quantity])
A19: =SUMIFS(Transactions[Total_Amount],Transactions[Date],">"&EOMONTH(C19,-1),Transactions[Date],"<="&C19) | B19: =SUMIFS(Transactions[Quantity],Transactions[Date],">"&EOMONTH(C19,-1),Transactions[Date],"<="&C19) | C19: =EOMONTH(C18,1) | E19: North | F19: =SUMIF(Transactions[Region],E19,Transactions[Total_Amount]) | H19: Furniture | I19: =SUMIF(Transactions[Category],H19,Transactions[Total_Amount]) | K19: Michael Brown | L19: =SUMIF(Transactions[Customer_ID],"CUST003",Transactions[Total_Amount]) | N19: Top Product | O19: Units | Q19: Headphones | R19: =SUMIF(Transactions[Product_Name],Q19,Transactions[Quantity])
A20: =SUMIFS(Transactions[Total_Amount],Transactions[Date],">"&EOMONTH(C20,-1),Transactions[Date],"<="&C20) | B20: =SUMIFS(Transactions[Quantity],Transactions[Date],">"&EOMONTH(C20,-1),Transactions[Date],"<="&C20) | C20: =EOMONTH(C19,1) | E20: South | F20: =SUMIF(Transactions[Region],E20,Transactions[Total_Amount]) | K20: Sarah Davis | L20: =SUMIF(Transactions[Customer_ID],"CUST004",Transactions[Total_Amount]) | N20: =INDEX(Q17:Q26,MATCH(MAX(R17:R26),R17:R26,0)) | O20: =MAX(R17:R26) | Q20: Coffee Maker | R20: =SUMIF(Transactions[Product_Name],Q20,Transactions[Quantity])
A21: =SUMIFS(Transactions[Total_Amount],Transactions[Date],">"&EOMONTH(C21,-1),Transactions[Date],"<="&C21) | B21: =SUMIFS(Transactions[Quantity],Transactions[Date],">"&EOMONTH(C21,-1),Transactions[Date],"<="&C21) | C21: =EOMONTH(C20,1) | E21: West | F21: =SUMIF(Transactions[Region],E21,Transactions[Total_Amount]) | K21: Lisa Anderson | L21: =SUMIF(Transactions[Customer_ID],"CUST006",Transactions[Total_Amount]) | Q21: Blender | R21: =SUMIF(Transactions[Product_Name],Q21,Transactions[Quantity])
A22: =SUMIFS(Transactions[Total_Amount],Transactions[Date],">"&EOMONTH(C22,-1),Transactions[Date],"<="&C22) | B22: =SUMIFS(Transactions[Quantity],Transactions[Date],">"&EOMONTH(C22,-1),Transactions[Date],"<="&C22) | C22: =EOMONTH(C21,1) | K22: David Martinez | L22: =SUMIF(Transactions[Customer_ID],"CUST007",Transactions[Total_Amount]) | Q22: Office Chair | R22: =SUMIF(Transactions[Product_Name],Q22,Transactions[Quantity])
A23: =SUMIFS(Transactions[Total_Amount],Transactions[Date],">"&EOMONTH(C23,-1),Transactions[Date],"<="&C23) | B23: =SUMIFS(Transactions[Quantity],Transactions[Date],">"&EOMONTH(C23,-1),Transactions[Date],"<="&C23) | C23: =EOMONTH(C22,1) | K23: Jennifer Taylor | L23: =SUMIF(Transactions[Customer_ID],"CUST008",Transactions[Total_Amount]) | Q23: Desk | R23: =SUMIF(Transactions[Product_Name],Q23,Transactions[Quantity])
A24: =SUMIFS(Transactions[Total_Amount],Transactions[Date],">"&EOMONTH(C24,-1),Transactions[Date],"<="&C24) | B24: =SUMIFS(Transactions[Quantity],Transactions[Date],">"&EOMONTH(C24,-1),Transactions[Date],"<="&C24) | C24: =EOMONTH(C23,1) | K24: Robert Thomas | L24: =SUMIF(Transactions[Customer_ID],"CUST009",Transactions[Total_Amount]) | Q24: Bookshelf | R24: =SUMIF(Transactions[Product_Name],Q24,Transactions[Quantity])
A25: =SUMIFS(Transactions[Total_Amount],Transactions[Date],">"&EOMONTH(C25,-1),Transactions[Date],"<="&C25) | B25: =SUMIFS(Transactions[Quantity],Transactions[Date],">"&EOMONTH(C25,-1),Transactions[Date],"<="&C25) | C25: =EOMONTH(C24,1) | K25: Maria Garcia | L25: =SUMIF(Transactions[Customer_ID],"CUST010",Transactions[Total_Amount]) | Q25: Monitor | R25: =SUMIF(Transactions[Product_Name],Q25,Transactions[Quantity])
A26: =SUMIFS(Transactions[Total_Amount],Transactions[Date],">"&EOMONTH(C26,-1),Transactions[Date],"<="&C26) | B26: =SUMIFS(Transactions[Quantity],Transactions[Date],">"&EOMONTH(C26,-1),Transactions[Date],"<="&C26) | C26: =EOMONTH(C25,1) | K26: William White | L26: =SUMIF(Transactions[Customer_ID],"CUST011",Transactions[Total_Amount]) | Q26: Keyboard | R26: =SUMIF(Transactions[Product_Name],Q26,Transactions[Quantity])
A27: =SUMIFS(Transactions[Total_Amount],Transactions[Date],">"&EOMONTH(C27,-1),Transactions[Date],"<="&C27) | B27: =SUMIFS(Transactions[Quantity],Transactions[Date],">"&EOMONTH(C27,-1),Transactions[Date],"<="&C27) | C27: =EOMONTH(C26,1) | K27: Patricia Moore | L27: =SUMIF(Transactions[Customer_ID],"CUST012",Transactions[Total_Amount])
A28: =SUMIFS(Transactions[Total_Amount],Transactions[Date],">"&EOMONTH(C28,-1),Transactions[Date],"<="&C28) | B28: =SUMIFS(Transactions[Quantity],Transactions[Date],">"&EOMONTH(C28,-1),Transactions[Date],"<="&C28) | C28: =EOMONTH(C27,1) | K28: Joseph Jackson | L28: =SUMIF(Transactions[Customer_ID],"CUST013",Transactions[Total_Amount])
A29: =SUMIFS(Transactions[Total_Amount],Transactions[Date],">"&EOMONTH(C29,-1),Transactions[Date],"<="&C29) | B29: =SUMIFS(Transactions[Quantity],Transactions[Date],">"&EOMONTH(C29,-1),Transactions[Date],"<="&C29) | C29: =EOMONTH(C28,1) | K29: Linda Martin | L29: =SUMIF(Transactions[Customer_ID],"CUST014",Transactions[Total_Amount])
A30: =SUMIFS(Transactions[Total_Amount],Transactions[Date],">"&EOMONTH(C30,-1),Transactions[Date],"<="&C30) | B30: =SUMIFS(Transactions[Quantity],Transactions[Date],">"&EOMONTH(C30,-1),Transactions[Date],"<="&C30) | C30: =EOMONTH(C29,1) | K30: Richard Lee | L30: =SUMIF(Transactions[Customer_ID],"CUST015",Transactions[Total_Amount])
K31: Elizabeth Hall | L31: =SUMIF(Transactions[Customer_ID],"CUST016",Transactions[Total_Amount])
K32: Charles Allen | L32: =SUMIF(Transactions[Customer_ID],"CUST017",Transactions[Total_Amount])
K33: Barbara Young | L33: =SUMIF(Transactions[Customer_ID],"CUST018",Transactions[Total_Amount])
A34: Regression (monthly revenue) | D34: Most frequent product | E34: =N20 | G34: Dynamic FILTER example | K34: Daniel King | L34: =SUMIF(Transactions[Customer_ID],"CUST019",Transactions[Total_Amount])
A35: Slope | B35: =SLOPE(A17:A30,ROW(A17:A30)-ROW(A17)+1) | D35: Top customer name | E35: =N17 | G35: =FILTER(Transactions[[Customer_Name]:[Total_Amount]],Transactions[Region]=Dashboard!B6,"No matching records") | K35: Margaret Wright | L35: =SUMIF(Transactions[Customer_ID],"CUST020",Transactions[Total_Amount])
A36: Intercept | B36: =INTERCEPT(A17:A30,ROW(A17:A30)-ROW(A17)+1) | K36: Kevin Scott | L36: =SUMIF(Transactions[Customer_ID],"CUST021",Transactions[Total_Amount])
D37: High-value customers | K37: Susan Green | L37: =SUMIF(Transactions[Customer_ID],"CUST022",Transactions[Total_Amount])
D38: Customer | E38: Revenue | K38: Paul Baker | L38: =SUMIF(Transactions[Customer_ID],"CUST023",Transactions[Total_Amount])
D39: =IFERROR(INDEX($K$17:$K$63,MATCH(LARGE($L$17:$L$63,1),$L$17:$L$63,0)),"") | E39: =IFERROR(LARGE($L$17:$L$63,1),"") | K39: Dorothy Nelson | L39: =SUMIF(Transactions[Customer_ID],"CUST024",Transactions[Total_Amount])
D40: =IFERROR(INDEX($K$17:$K$63,MATCH(LARGE($L$17:$L$63,2),$L$17:$L$63,0)),"") | E40: =IFERROR(LARGE($L$17:$L$63,2),"") | K40: Mark Carter | L40: =SUMIF(Transactions[Customer_ID],"CUST025",Transactions[Total_Amount])
D41: =IFERROR(INDEX($K$17:$K$63,MATCH(LARGE($L$17:$L$63,3),$L$17:$L$63,0)),"") | E41: =IFERROR(LARGE($L$17:$L$63,3),"") | K41: Karen Hill | L41: =SUMIF(Transactions[Customer_ID],"CUST026",Transactions[Total_Amount])
D42: =IFERROR(INDEX($K$17:$K$63,MATCH(LARGE($L$17:$L$63,4),$L$17:$L$63,0)),"") | E42: =IFERROR(LARGE($L$17:$L$63,4),"") | K42: George Adams | L42: =SUMIF(Transactions[Customer_ID],"CUST027",Transactions[Total_Amount])
D43: =IFERROR(INDEX($K$17:$K$63,MATCH(LARGE($L$17:$L$63,5),$L$17:$L$63,0)),"") | E43: =IFERROR(LARGE($L$17:$L$63,5),"") | K43: Betty Campbell | L43: =SUMIF(Transactions[Customer_ID],"CUST028",Transactions[Total_Amount])
...

Sheet Visualizations
A1: SALES VISUALIZATIONS

Sheet Dashboard
B2: DATA INTELLIGENCE DASHBOARD
B4: Region Filter | C4: All | E4: Category Filter | F4: All | H4: Segment Filter | I4: All
B6: TOTAL REVENUE | E6: TRANSACTIONS | H6: AVG ORDER VALUE
B7: =SUMIFS(Transactions[Total_Amount],Transactions[Region],IF($C$4="All","*",$C$4),Transactions[Category],IF($F$4="All","*",$F$4),Transactions[Customer_Segment],IF($I$4="All","*",$I$4)) | E7: =COUNTIFS(Transactions[Region],IF($C$4="All","*",$C$4),Transactions[Category],IF($F$4="All","*",$F$4),Transactions[Customer_Segment],IF($I$4="All","*",$I$4)) | H7: =IFERROR(B7/E7,0)
B10: Top customer | C10: =Analysis!N17 | E10: Best-selling product | F10: =Analysis!N20 | H10: Refreshed | I10: =NOW()
B11: Top customer revenue | C11: =Analysis!O17 | E11: Units sold | F11: =Analysis!O20
